Action number: 2
 80% (318 of 396) |#########################################################################                  | Elapsed Time: 0:04:03 ETA:   0:00:20Traceback (most recent call last):
  File "C:\Python36\lib\site-packages\urllib3\connectionpool.py", line 601, in urlopen
    chunked=chunked)
  File "C:\Python36\lib\site-packages\urllib3\connectionpool.py", line 387, in _make_request
    six.raise_from(e, None)
  File "<string>", line 2, in raise_from
  File "C:\Python36\lib\site-packages\urllib3\connectionpool.py", line 383, in _make_request
    httplib_response = conn.getresponse()
  File "C:\Python36\lib\http\client.py", line 1331, in getresponse
    response.begin()
  File "C:\Python36\lib\http\client.py", line 297, in begin
    version, status, reason = self._read_status()
  File "C:\Python36\lib\http\client.py", line 258, in _read_status
    line = str(self.fp.readline(_MAXLINE + 1), "iso-8859-1")
  File "C:\Python36\lib\socket.py", line 586, in readinto
    return self._sock.recv_into(b)
  File "C:\Python36\lib\ssl.py", line 1009, in recv_into
    return self.read(nbytes, buffer)
  File "C:\Python36\lib\ssl.py", line 871, in read
    return self._sslobj.read(len, buffer)
  File "C:\Python36\lib\ssl.py", line 631, in read
    v = self._sslobj.read(len, buffer)
TimeoutError: [WinError 10060] A connection attempt failed because the connected party did not properly respond after a period of time, or established connection failed because connected host has failed to respond

During handling of the above exception, another exception occurred:

Traceback (most recent call last):
  File "C:\Python36\lib\site-packages\requests\adapters.py", line 440, in send
    timeout=timeout
  File "C:\Python36\lib\site-packages\urllib3\connectionpool.py", line 639, in urlopen
    _stacktrace=sys.exc_info()[2])
  File "C:\Python36\lib\site-packages\urllib3\util\retry.py", line 357, in increment
    raise six.reraise(type(error), error, _stacktrace)
  File "C:\Python36\lib\site-packages\urllib3\packages\six.py", line 685, in reraise
    raise value.with_traceback(tb)
  File "C:\Python36\lib\site-packages\urllib3\connectionpool.py", line 601, in urlopen
    chunked=chunked)
  File "C:\Python36\lib\site-packages\urllib3\connectionpool.py", line 387, in _make_request
    six.raise_from(e, None)
  File "<string>", line 2, in raise_from
  File "C:\Python36\lib\site-packages\urllib3\connectionpool.py", line 383, in _make_request
    httplib_response = conn.getresponse()
  File "C:\Python36\lib\http\client.py", line 1331, in getresponse
    response.begin()
  File "C:\Python36\lib\http\client.py", line 297, in begin
    version, status, reason = self._read_status()
  File "C:\Python36\lib\http\client.py", line 258, in _read_status
    line = str(self.fp.readline(_MAXLINE + 1), "iso-8859-1")
  File "C:\Python36\lib\socket.py", line 586, in readinto
    return self._sock.recv_into(b)
  File "C:\Python36\lib\ssl.py", line 1009, in recv_into
    return self.read(nbytes, buffer)
  File "C:\Python36\lib\ssl.py", line 871, in read
    return self._sslobj.read(len, buffer)
  File "C:\Python36\lib\ssl.py", line 631, in read
    v = self._sslobj.read(len, buffer)
urllib3.exceptions.ProtocolError: ('Connection aborted.', TimeoutError(10060, 'A connection attempt failed because the connected party did not properly respond after a period of time, or established connection failed because connected host has failed to respond', None, 10060, None))

During handling of the above exception, another exception occurred:

Traceback (most recent call last):
  File "C:\Users\an-ehs\repos\pymkm\main.py", line 280, in <module>
    main()
  File "C:\Users\an-ehs\repos\pymkm\main.py", line 50, in main
    update_stock_prices_to_trend(api=api)
  File "C:\Users\an-ehs\repos\pymkm\pymkm.py", line 28, in __call__
    self.function(*arg, **kwargs)
  File "C:\Users\an-ehs\repos\pymkm\main.py", line 142, in update_stock_prices_to_trend
    r = api.get_product(article['idProduct'])
  File "C:\Users\an-ehs\repos\pymkm\pymkm.py", line 138, in get_product
    r = mkm_oauth.get(url)
  File "C:\Python36\lib\site-packages\requests\sessions.py", line 521, in get
    return self.request('GET', url, **kwargs)
  File "C:\Python36\lib\site-packages\requests\sessions.py", line 508, in request
    resp = self.send(prep, **send_kwargs)
  File "C:\Python36\lib\site-packages\requests\sessions.py", line 618, in send
    r = adapter.send(request, **kwargs)
  File "C:\Python36\lib\site-packages\requests\adapters.py", line 490, in send
    raise ConnectionError(err, request=request)
requests.exceptions.ConnectionError: ('Connection aborted.', TimeoutError(10060, 'A connection attempt failed because the connected party did not properly respond after a period of time, or established connection failed because connected host has failed to respond', None, 10060, None))